Workbook

Sheet Read Me
A1: KSA Construction Estimating Suite - master estimate workbook
A2: Purpose
A3: An editable, auditable view of one estimate. The Python application is the AUTHORITATIVE calculation and validation engine; Excel formulas exist for transparency and are re-verified (recalculated and compared) when the workbook is validated or re-imported.
A4: Human responsibilities (never delegated to software or AI)
A5: 1. Quantity take-off is performed by a human estimator with their chosen tool and imported here; the application never measures drawings or alters imported quantities.
A6: 2. Every rate, assumption, assembly, quotation, supplier selection, project duration, indirect allocation, commercial policy, exclusion, clarification resolution and the final estimate/tender export needs an explicit human approval in the application.
A7: 3. Missing rates are shown as missing (blank), never as zero, and create procurement requirements. Synthetic demonstration figures are labelled SYNTHETIC / DEMO / NOT A MARKET QUOTE.
A8: How to use
A9: Yellow cells are inputs. Grey cells are formulas (locked). Blue cells are read-only values from the application. Sheets are protected without a password to prevent accidents - not as a security control.
A10: Edit input cells and re-import into the application: the importer re-validates everything, creates DRAFT / PENDING proposals only, and ignores any attempt to write approval statuses.
A11: Calculation strategy
A12: openpyxl writes formulas without cached values. Excel recalculates on open (fullCalcOnLoad). For verification the application recalculates a COPY with LibreOffice (headless) and compares formula results with its own Decimal engine ('Check' columns and Project Summary).
... A15: Resource, assembly, assumption, quotation, vendor, clarification and procurement IDs are stable across all workbooks and the database.

Sheet Project Setup
A1: Project Setup
A2: Project-level facts. Edit yellow cells and re-import; the application validates them.
A3: Legend: yellow = input | grey = formula (locked) | blue = read-only from the application. Python application is the authoritative calculator.
A5: Field | B5: Value | C5: Note
A6: Project ID | C6: Stable ID across workbooks and database
A7: Project name
A8: Client
A9: Location
A10: Region | C10: Rate applicability only - no regional multiplier is applied
A11: Currency | B11: SAR
A12: Design stage
A13: Tender reference
A14: Default tax category | C14: Rate comes from the approved tax-category table
A15: Rate as-of date | C15: Rates/quotations must be valid on this date
A16: Commercial policy | C16: Approved by a Commercial Approver in the application
A17: Demonstration project | B17: No
A18: Estimate state | C18: Complete / Complete with Provisional Inputs / Preliminary — Incomplete
A19: Estimate fingerprint | C19: Used to detect stale exports
A20: Generated (UTC) | B20: 2026-10-12T20:30:35+00:00
A21: Application version | B21: 0.1.0

Sheet Project Summary
A1: Project Summary
A2: Workbook formulas vs the application's authoritative values. Any MISMATCH means formulas were edited or are stale: re-export or validate.
A3: Legend: yellow = input | grey = formula (locked) | blue = read-only from the application. Python application is the authoritative calculator.
A5: Measure | B5: Workbook (formula) | C5: Application (engine) | D5: Check | E5: Note
A6: Direct cost (SAR) | B6: ='Direct Cost Build-Up'!K307 | D6: =IF(OR(B6="",C6=""),"n/a",IF(ABS(B6-C6)>0.01,"MISMATCH","OK")) | E6: Sum of engine line amounts
A7: Indirect cost (SAR) | B7: ='Indirect Costs'!K307 | D7: =IF(OR(B7="",C7=""),"n/a",IF(ABS(B7-C7)>0.01,"MISMATCH","OK"))
A8: Total cost (SAR) | B8: ='Commercial Calculation'!B16 | D8: =IF(OR(B8="",C8=""),"n/a",IF(ABS(B8-C8)>0.01,"MISMATCH","OK"))
A9: Net price before tax (SAR) | B9: ='Commercial Calculation'!B26 | D9: =IF(OR(B9="",C9=""),"n/a",IF(ABS(B9-C9)>0.01,"MISMATCH","OK")) | E9: Commercial chain
A10: Pricing schedule total (SAR) | B10: ='Pricing Schedule'!F307 | D10: =IF(OR(B10="",C10=""),"n/a",IF(ABS(B10-C10)>0.01,"MISMATCH","OK")) | E10: Tendered amounts (rounded unit rates)
A11: Tax (SAR) | B11: ='Commercial Calculation'!B29 | D11: =IF(OR(B11="",C11=""),"n/a",IF(ABS(B11-C11)>0.01,"MISMATCH","OK"))
A12: Final payable (SAR) | B12: ='Commercial Calculation'!B30 | D12: =IF(OR(B12="",C12=""),"n/a",IF(ABS(B12-C12)>0.01,"MISMATCH","OK"))

Sheet Trade and Cost Code Mapping
A1: Trade and Cost Code Mapping
A2: Map each BOQ item to an internal cost code and an approved assembly. Mapping suggestions (heuristic/AI) stay 'Suggested' until a human approves them in the application. Cost-code taxonomy is listed on the right for reference.
A3: BLANK TEMPLATE | Legend: yellow = input | grey = formula (locked) | blue = read-only from the application. Python application is the authoritative calculator.
A4: item_key | B4: item_code | C4: description | D4: trade | E4: cost_code | F4: assembly_code | G4: mapping_status | H4: mapping_source | I4: pricing_method
A5: BOQ item key | B5: Client code | C5: Description | D5: Client trade | E5: Cost code | F5: Assembly code | G5: Mapping status | H5: Mapping source | I5: Pricing method

Sheet Pricing Schedule
A1: Pricing Schedule (client-facing basis)
A2: Tendered unit rates and amounts from the application. Amount = ROUND(quantity x unit rate, 2). 'Engine amount' is the authoritative application value; 'Check' flags any difference (stale or edited formula).
A3: BLANK TEMPLATE | Legend: yellow = input | grey = formula (locked) | blue = read-only from the application. Python application is the authoritative calculator.
A4: item_code | B4: description | C4: unit | D4: quantity | E4: unit_rate | F4: amount | G4: engine_amount | H4: check | I4: status | J4: flags
A5: Item | B5: Description | C5: Unit | D5: Quantity | E5: Unit rate (SAR) | F5: Amount (SAR) | G5: Engine amount | H5: Check | I5: Status | J5: Flags
F6: =IF(OR(D6="",E6=""),"",ROUND(D6*E6,2)) | H6: =IF(OR(F6="",G6=""),"",IF(ABS(F6-G6)>0.01,"MISMATCH","OK"))
F7: =IF(OR(D7="",E7=""),"",ROUND(D7*E7,2)) | H7: =IF(OR(F7="",G7=""),"",IF(ABS(F7-G7)>0.01,"MISMATCH","OK"))
F8: =IF(OR(D8="",E8=""),"",ROUND(D8*E8,2)) | H8: =IF(OR(F8="",G8=""),"",IF(ABS(F8-G8)>0.01,"MISMATCH","OK"))
F9: =IF(OR(D9="",E9=""),"",ROUND(D9*E9,2)) | H9: =IF(OR(F9="",G9=""),"",IF(ABS(F9-G9)>0.01,"MISMATCH","OK"))
F10: =IF(OR(D10="",E10=""),"",ROUND(D10*E10,2)) | H10: =IF(OR(F10="",G10=""),"",IF(ABS(F10-G10)>0.01,"MISMATCH","OK"))
F11: =IF(OR(D11="",E11=""),"",ROUND(D11*E11,2)) | H11: =IF(OR(F11="",G11=""),"",IF(ABS(F11-G11)>0.01,"MISMATCH","OK"))
F12: =IF(OR(D12="",E12=""),"",ROUND(D12*E12,2)) | H12: =IF(OR(F12="",G12=""),"",IF(ABS(F12-G12)>0.01,"MISMATCH","OK"))
F13: =IF(OR(D13="",E13=""),"",ROUND(D13*E13,2)) | H13: =IF(OR(F13="",G13=""),"",IF(ABS(F13-G13)>0.01,"MISMATCH","OK"))
F14: =IF(OR(D14="",E14=""),"",ROUND(D14*E14,2)) | H14: =IF(OR(F14="",G14=""),"",IF(ABS(F14-G14)>0.01,"MISMATCH","OK"))
F15: =IF(OR(D15="",E15=""),"",ROUND(D15*E15,2)) | H15: =IF(OR(F15="",G15=""),"",IF(ABS(F15-G15)>0.01,"MISMATCH","OK"))
F16: =IF(OR(D16="",E16=""),"",ROUND(D16*E16,2)) | H16: =IF(OR(F16="",G16=""),"",IF(ABS(F16-G16)>0.01,"MISMATCH","OK"))
F17: =IF(OR(D17="",E17=""),"",ROUND(D17*E17,2)) | H17: =IF(OR(F17="",G17=""),"",IF(ABS(F17-G17)>0.01,"MISMATCH","OK"))
... F305: =IF(OR(D305="",E305=""),"",ROUND(D305*E305,2)) | H305: =IF(OR(F305="",G305=""),"",IF(ABS(F305-G305)>0.01,"MISMATCH","OK"))
A307: TOTAL | F307: =SUM(F6:F305) | G307: =SUM(G6:G305)

Sheet BOQ Import
A1: BOQ Import (measured quantities)
A2: Quantities are measured by the estimator in the tool of choice and imported here; the application never measures or alters them. Re-import is safe: differences become pending change requests. Required: Description, Unit, Quantity.
A3: BLANK TEMPLATE | Legend: yellow = input | grey = formula (locked) | blue = read-only from the application. Python application is the authoritative calculator.
A4: item_code | B4: description | C4: trade | D4: unit | E4: quantity | F4: client_rate | G4: client_amount | H4: drawing_ref | I4: spec_ref | J4: cost_code | K4: revision | L4: source_file | M4: source_sheet | N4: source_row | O4: quantity_original | P4: unit_status | Q4: validation_status | R4: issues
A5: Item | B5: Description | C5: Trade | D5: Unit | E5: Quantity | F5: Client rate | G5: Client amount | H5: Drawing ref | I5: Spec ref | J5: Cost code | K5: Revision | L5: Source file | M5: Source sheet | N5: Source row | O5: Original qty text | P5: Unit status | Q5: Validation | R5: Issues

Sheet Direct Cost Build-Up
A1: Direct Cost Build-Up
A2: One row per resource line: quantity x rate. Unpriced lines are blank (never zero) and listed with their exception. Amount formula = ROUND(qty x rate, 2); 'Engine amount' is authoritative.
A3: BLANK TEMPLATE | Legend: yellow = input | grey = formula (locked) | blue = read-only from the application. Python application is the authoritative calculator.
A4: item_key | B4: assembly | C4: line_ref | D4: kind | E4: resource_id | F4: description | G4: quantity | H4: unit | I4: rate | J4: amount | K4: engine_amount | L4: check | M4: rate_type | N4: rate_status | O4: eligibility | P4: basis | Q4: flags
A5: BOQ item | B5: Assembly | C5: Line ref | D5: Kind | E5: Resource ID | F5: Description | G5: Quantity | H5: Unit | I5: Rate (SAR) | J5: Amount (SAR) | K5: Engine amount | L5: Check | M5: Rate type | N5: Rate status | O5: Eligibility | P5: Calculation basis | Q5: Flags
J6: =IF(OR(G6="",I6=""),"",ROUND(G6*I6,2)) | L6: =IF(OR(J6="",K6=""),"",IF(ABS(J6-K6)>0.01,"MISMATCH","OK"))
J7: =IF(OR(G7="",I7=""),"",ROUND(G7*I7,2)) | L7: =IF(OR(J7="",K7=""),"",IF(ABS(J7-K7)>0.01,"MISMATCH","OK"))
J8: =IF(OR(G8="",I8=""),"",ROUND(G8*I8,2)) | L8: =IF(OR(J8="",K8=""),"",IF(ABS(J8-K8)>0.01,"MISMATCH","OK"))
J9: =IF(OR(G9="",I9=""),"",ROUND(G9*I9,2)) | L9: =IF(OR(J9="",K9=""),"",IF(ABS(J9-K9)>0.01,"MISMATCH","OK"))
J10: =IF(OR(G10="",I10=""),"",ROUND(G10*I10,2)) | L10: =IF(OR(J10="",K10=""),"",IF(ABS(J10-K10)>0.01,"MISMATCH","OK"))
J11: =IF(OR(G11="",I11=""),"",ROUND(G11*I11,2)) | L11: =IF(OR(J11="",K11=""),"",IF(ABS(J11-K11)>0.01,"MISMATCH","OK"))
J12: =IF(OR(G12="",I12=""),"",ROUND(G12*I12,2)) | L12: =IF(OR(J12="",K12=""),"",IF(ABS(J12-K12)>0.01,"MISMATCH","OK"))
J13: =IF(OR(G13="",I13=""),"",ROUND(G13*I13,2)) | L13: =IF(OR(J13="",K13=""),"",IF(ABS(J13-K13)>0.01,"MISMATCH","OK"))
J14: =IF(OR(G14="",I14=""),"",ROUND(G14*I14,2)) | L14: =IF(OR(J14="",K14=""),"",IF(ABS(J14-K14)>0.01,"MISMATCH","OK"))
J15: =IF(OR(G15="",I15=""),"",ROUND(G15*I15,2)) | L15: =IF(OR(J15="",K15=""),"",IF(ABS(J15-K15)>0.01,"MISMATCH","OK"))
J16: =IF(OR(G16="",I16=""),"",ROUND(G16*I16,2)) | L16: =IF(OR(J16="",K16=""),"",IF(ABS(J16-K16)>0.01,"MISMATCH","OK"))
J17: =IF(OR(G17="",I17=""),"",ROUND(G17*I17,2)) | L17: =IF(OR(J17="",K17=""),"",IF(ABS(J17-K17)>0.01,"MISMATCH","OK"))
... J305: =IF(OR(G305="",I305=""),"",ROUND(G305*I305,2)) | L305: =IF(OR(J305="",K305=""),"",IF(ABS(J305-K305)>0.01,"MISMATCH","OK"))
A307: TOTAL | J307: =SUM(J6:J305) | K307: =SUM(K6:K305)

Sheet Labour Library
A1: Labour Library
A2: Resource definitions with their current APPROVED rate (blue, read-only). Enter a proposed rate in the yellow columns: it is imported as a Draft proposal and needs review/approval in the application. A blank rate means the rate is MISSING - it is never treated as zero.
A3: BLANK TEMPLATE | Legend: yellow = input | grey = formula (locked) | blue = read-only from the application. Python application is the authoritative calculator.
A4: id | B4: cost_code | C4: category | D4: description | E4: specification | F4: unit | G4: rate | H4: currency | I4: rate_type | J4: rate_status | K4: price_date | L4: valid_until | M4: supplier | N4: evidence | O4: confidence | P4: region | Q4: new_rate | R4: new_rate_type | S4: new_currency | T4: new_price_date | U4: new_valid_until | V4: new_evidence
A5: Resource ID | B5: Cost code | C5: Category | D5: Description | E5: Specification | F5: Unit | G5: Current approved rate | H5: Currency | I5: Rate type | J5: Rate status | K5: Price date | L5: Valid until | M5: Supplier | N5: Source / evidence | O5: Confidence | P5: Region | Q5: PROPOSED new rate | R5: Proposed rate type | S5: Proposed currency | T5: Proposed price date | U5: Proposed valid until | V5: Proposed source / evidence

Sheet Material Library
A1: Material Library
A2: Resource definitions with their current APPROVED rate (blue, read-only). Enter a proposed rate in the yellow columns: it is imported as a Draft proposal and needs review/approval in the application. A blank rate means the rate is MISSING - it is never treated as zero.
A3: BLANK TEMPLATE | Legend: yellow = input | grey = formula (locked) | blue = read-only from the application. Python application is the authoritative calculator.
A4: id | B4: cost_code | C4: category | D4: description | E4: specification | F4: unit | G4: rate | H4: currency | I4: rate_type | J4: rate_status | K4: price_date | L4: valid_until | M4: supplier | N4: evidence | O4: confidence | P4: region | Q4: new_rate | R4: new_rate_type | S4: new_currency | T4: new_price_date | U4: new_valid_until | V4: new_evidence
A5: Resource ID | B5: Cost code | C5: Category | D5: Description | E5: Specification | F5: Unit | G5: Current approved rate | H5: Currency | I5: Rate type | J5: Rate status | K5: Price date | L5: Valid until | M5: Supplier | N5: Source / evidence | O5: Confidence | P5: Region | Q5: PROPOSED new rate | R5: Proposed rate type | S5: Proposed currency | T5: Proposed price date | U5: Proposed valid until | V5: Proposed source / evidence

Sheet Plant and Equipment Library
A1: Plant and Equipment Library
A2: Resource definitions with their current APPROVED rate (blue, read-only). Enter a proposed rate in the yellow columns: it is imported as a Draft proposal and needs review/approval in the application. A blank rate means the rate is MISSING - it is never treated as zero.
A3: BLANK TEMPLATE | Legend: yellow = input | grey = formula (locked) | blue = read-only from the application. Python application is the authoritative calculator.
A4: id | B4: cost_code | C4: category | D4: description | E4: specification | F4: unit | G4: rate | H4: currency | I4: rate_type | J4: rate_status | K4: price_date | L4: valid_until | M4: supplier | N4: evidence | O4: confidence | P4: region | Q4: new_rate | R4: new_rate_type | S4: new_currency | T4: new_price_date | U4: new_valid_until | V4: new_evidence
A5: Resource ID | B5: Cost code | C5: Category | D5: Description | E5: Specification | F5: Unit | G5: Current approved rate | H5: Currency | I5: Rate type | J5: Rate status | K5: Price date | L5: Valid until | M5: Supplier | N5: Source / evidence | O5: Confidence | P5: Region | Q5: PROPOSED new rate | R5: Proposed rate type | S5: Proposed currency | T5: Proposed price date | U5: Proposed valid until | V5: Proposed source / evidence

Sheet Subcontract Library
A1: Subcontract Library
A2: Resource definitions with their current APPROVED rate (blue, read-only). Enter a proposed rate in the yellow columns: it is imported as a Draft proposal and needs review/approval in the application. A blank rate means the rate is MISSING - it is never treated as zero.
A3: BLANK TEMPLATE | Legend: yellow = input | grey = formula (locked) | blue = read-only from the application. Python application is the authoritative calculator.
A4: id | B4: cost_code | C4: category | D4: description | E4: specification | F4: unit | G4: rate | H4: currency | I4: rate_type | J4: rate_status | K4: price_date | L4: valid_until | M4: supplier | N4: evidence | O4: confidence | P4: region | Q4: new_rate | R4: new_rate_type | S4: new_currency | T4: new_price_date | U4: new_valid_until | V4: new_evidence
A5: Resource ID | B5: Cost code | C5: Category | D5: Description | E5: Specification | F5: Unit | G5: Current approved rate | H5: Currency | I5: Rate type | J5: Rate status | K5: Price date | L5: Valid until | M5: Supplier | N5: Source / evidence | O5: Confidence | P5: Region | Q5: PROPOSED new rate | R5: Proposed rate type | S5: Proposed currency | T5: Proposed price date | U5: Proposed valid until | V5: Proposed source / evidence

Sheet Assembly Library
A1: Assembly Library (one row per assembly line)
A2: Assemblies are versioned; approved versions are immutable. Edits are imported as a NEW draft version for review. Waste: set ONE basis only (factor already includes waste, or fixed %, or assumption reference). Labour needs an explicit productivity basis.
A3: BLANK TEMPLATE | Legend: yellow = input | grey = formula (locked) | blue = read-only from the application. Python application is the authoritative calculator.
A4: assembly_code | B4: version | C4: status | D4: description | E4: unit | F4: cost_code | G4: line_no | H4: line_type | I4: resource_id | J4: child_assembly_code | K4: factor | L4: factor_unit | M4: factor_includes_waste | N4: waste_basis | O4: waste_value | P4: waste_ref | Q4: productivity_basis | R4: crew | S4: includes_labour | T4: includes_material | U4: includes_plant | V4: utilisation_basis | W4: utilisation_value | X4: utilisation_ref | Y4: confidence | Z4: source
A5: Assembly code | B5: Version | C5: Status | D5: Assembly description | E5: Unit | F5: Cost code | G5: Line | H5: Line type | I5: Resource ID | J5: Nested assembly | K5: Factor / output | L5: Factor unit | M5: Factor incl. waste (1/0) | N5: Waste basis | O5: Waste % | P5: Waste assumption ID | Q5: Productivity basis | R5: Crew (resource:count;...) | S5: Sub incl. labour | T5: Sub incl. material | U5: Sub incl. plant | V5: Utilisation basis | W5: Utilisation % | X5: Utilisation assumption | Y5: Confidence | Z5: Source

Sheet Assumptions Register
A1: Assumptions Register
A2: Effective value for this project (blue). To propose a project override, enter the value and a reason in the yellow columns; it is imported as 'Pending Review' and never changes the global library.
A3: BLANK TEMPLATE | Legend: yellow = input | grey = formula (locked) | blue = read-only from the application. Python application is the authoritative calculator.
A4: id | B4: family | C4: name | D4: description | E4: applies_to | F4: value | G4: unit | H4: status | I4: origin | J4: engine_key | K4: confidence | L4: override_value | M4: override_reason
A5: Assumption ID | B5: Family | C5: Name | D5: Description | E5: Applies to | F5: Effective value | G5: Unit | H5: Status | I5: Origin | J5: Engine key | K5: Confidence | L5: PROPOSED project value | M5: Reason for override

Sheet Indirect Costs
A1: Indirect Costs & Project Duration
A2: Fixed, percentage and duration-based costs. Project duration must be approved before duration-based items calculate. Items included in a subcontract quotation are excluded to avoid double counting.
A3: BLANK TEMPLATE | Legend: yellow = input | grey = formula (locked) | blue = read-only from the application. Python application is the authoritative calculator.
A4: code | B4: category | C4: description | D4: method | E4: amount | F4: quantity | G4: allocation_method | H4: allocation_target | I4: included_in_subcontract | J4: status | K4: engine_amount | L4: basis
A5: Code | B5: Category | C5: Description | D5: Method | E5: Rate / amount | F5: Quantity (people/units) | G5: Allocation | H5: Alloc. target | I5: Incl. in subcontract (1/0) | J5: Status | K5: Calculated amount | L5: Calculation basis
A307: TOTAL | K307: =SUM(K6:K305)

Sheet Commercial Calculation
A1: Commercial Calculation (formula mirror of the application engine)
A2: Order: direct + indirect = C0; + contingency + risk + escalation = total cost; selling price by the SELECTED method; less discount; commercial rounding; tax on the tendered schedule total. Each adder is applied once from its stated base. 'Engine' is authoritative; 'Diff' flags stale/edited formulas.
A3: Legend: yellow = input | grey = formula (locked) | blue = read-only from the application. Python application is the authoritative calculator.
A5: Step | B5: Workbook value / input | C5: Basis / formula | D5: Engine value | E5: Diff | F5: Note
A6: Direct cost (SAR) | F6: From Direct Cost Build-Up
A7: Indirect cost (SAR) | F7: From Indirect Costs (approved items only)
A8: Pre-contingency cost C0 | B8: =B6+B7 | C8: formula | F8: Direct + indirect
A9: Contingency % | F9: Percent points
A10: Contingency base (direct | direct_indirect) | F10: Base must be explicit
A11: Contingency amount | B11: =ROUND(B9/100*IF(B10="direct",B6,B6+B7),2) | C11: formula
A12: Risk allowances (SAR) | F12: Itemised in the commercial policy (percent items or fixed amounts)
A13: Escalation %
A14: Escalation base (direct | direct_indirect | cost_before_escalation)
A15: Escalation amount | B15: =ROUND(B13/100*IF(B14="direct",B6,IF(B14="direct_indirect",B6+B7,B8+B11+B12)),2) | C15: formula
A16: Total cost T | B16: =B8+B11+B12+B15 | C16: formula | F16: C0 + contingency + risk + escalation
A17: Method (markup | margin) | F17: Clearly labelled selection - no universal policy is assumed
A18: Markup % (on cost) | F18: Selling = Cost x (1 + markup)
A19: Gross margin % (of selling price) | F19: Selling = Cost / (1 - margin)
A20: Selling price before discount | B20: =ROUND(IF(B17="markup",B16*(1+B18/100),B16/(1-B19/100)),2) | C20: formula
A21: Discount %
A22: Discount fixed amount (SAR) | F22: Use % OR amount
A23: Discount amount | B23: =IF(B21<>"",ROUND(B20*B21/100,2),IF(B22<>"",B22,0)) | C23: formula
A24: Net price before rounding | B24: =B20-B23 | C24: formula
A25: Rounding step (SAR, blank = 2dp) | F25: Configurable commercial rounding
A26: Net price (rounded, before tax) | B26: =IF(AND(B25<>"",B25>0),ROUND(B24/B25,0)*B25,ROUND(B24,2)) | C26: formula
A27: Pricing schedule total (tendered, before tax) | F27: Sum of rounded schedule amounts; variance to net price is reported, never hidden
A28: Tax rate % (single category) | F28: From the approved, date-valid tax category. Multiple categories: see engine value
A29: Tax | B29: =IF(B28="","",ROUND(B27*B28/100,2)) | C29: formula
A30: Final payable (incl. tax) | B30: =IF(B29="","",B27+B29) | C30: formula
A33: Cost reconciliation (engine trace: resource level to selling price)

Sheet Procurement Register
A1: Procurement Register
A2: Missing, expired, unapproved and low-confidence rates become procurement requirements. RFQs are drafted (never sent) from this register.
A3: BLANK TEMPLATE | Legend: yellow = input | grey = formula (locked) | blue = read-only from the application. Python application is the authoritative calculator.
A4: id | B4: package_id | C4: trade | D4: resource_id | E4: description | F4: specification | G4: quantity | H4: unit | I4: delivery_location | J4: required_date | K4: preferred_suppliers | L4: reason | M4: estimated_exposure | N4: rfq_status | O4: response_deadline | P4: quotation_status | Q4: approval_status
A5: Item ID | B5: Package | C5: Trade | D5: Resource | E5: Description | F5: Specification | G5: Quantity | H5: Unit | I5: Delivery location | J5: Required date | K5: Preferred suppliers | L5: Reason | M5: Indicative exposure (SAR) | N5: RFQ status | O5: Response deadline | P5: Quotation status | Q5: Approval status

Sheet Vendor Directory
A1: Vendor Directory
A2: No contact detail may be entered without a traceable source and permitted use. Never copy contacts from unverified places. Contacts are optional.
A3: BLANK TEMPLATE | Legend: yellow = input | grey = formula (locked) | blue = read-only from the application. Python application is the authoritative calculator.
A4: id | B4: name | C4: supplier_type | D4: trades | E4: region | F4: contact_name | G4: contact_email | H4: contact_phone | I4: contact_source | J4: qualification_status | K4: is_synthetic
A5: Vendor ID | B5: Name | C5: Type | D5: Trades (cost codes) | E5: Region | F5: Contact | G5: Email | H5: Phone | I5: Contact source (required if contact given) | J5: Qualification | K5: Synthetic (1/0)

Sheet Vendor Quotations
A1: Vendor Quotations (one row per quotation line)
A2: Enter or import supplier quotations. Imported quotations start as Draft; a Procurement Reviewer verifies them against the supplier's document. AI-extracted values must be checked by a human.
A3: BLANK TEMPLATE | Legend: yellow = input | grey = formula (locked) | blue = read-only from the application. Python application is the authoritative calculator.
A4: quotation_id | B4: supplier_id | C4: reference | D4: quote_date | E4: valid_until | F4: currency | G4: tax_treatment | H4: tax_rate_pct | I4: payment_terms | J4: status | K4: line_no | L4: procurement_item_id | M4: description | N4: quantity | O4: unit | P4: unit_rate | Q4: discount_pct | R4: extended | S4: delivery_included | T4: unloading_included | U4: lead_time_days | V4: compliance | W4: comments
A5: Quotation ID | B5: Vendor ID | C5: Supplier ref | D5: Quote date | E5: Valid until | F5: Currency | G5: Tax (excl/incl/exempt) | H5: Tax rate % | I5: Payment terms | J5: Status | K5: Line | L5: Procurement item | M5: Description | N5: Qty | O5: Unit | P5: Unit rate | Q5: Disc % | R5: Extended (qty x rate x (1-disc)) | S5: Delivery incl. | T5: Unloading incl. | U5: Lead time (days) | V5: Compliance | W5: Comments / deviations
R6: =IF(OR(N6="",P6=""),"",N6*P6*(1-IF(Q6="",0,Q6)/100))
R7: =IF(OR(N7="",P7=""),"",N7*P7*(1-IF(Q7="",0,Q7)/100))
R8: =IF(OR(N8="",P8=""),"",N8*P8*(1-IF(Q8="",0,Q8)/100))
R9: =IF(OR(N9="",P9=""),"",N9*P9*(1-IF(Q9="",0,Q9)/100))
R10: =IF(OR(N10="",P10=""),"",N10*P10*(1-IF(Q10="",0,Q10)/100))
R11: =IF(OR(N11="",P11=""),"",N11*P11*(1-IF(Q11="",0,Q11)/100))
R12: =IF(OR(N12="",P12=""),"",N12*P12*(1-IF(Q12="",0,Q12)/100))
R13: =IF(OR(N13="",P13=""),"",N13*P13*(1-IF(Q13="",0,Q13)/100))
R14: =IF(OR(N14="",P14=""),"",N14*P14*(1-IF(Q14="",0,Q14)/100))
R15: =IF(OR(N15="",P15=""),"",N15*P15*(1-IF(Q15="",0,Q15)/100))
R16: =IF(OR(N16="",P16=""),"",N16*P16*(1-IF(Q16="",0,Q16)/100))
R17: =IF(OR(N17="",P17=""),"",N17*P17*(1-IF(Q17="",0,Q17)/100))
... R305: =IF(OR(N305="",P305=""),"",N305*P305*(1-IF(Q305="",0,Q305)/100))
A307: TOTAL | R307: =SUM(R6:R305)

Sheet Quote Comparison
A1: Quote Comparison (levelled)
A2: Actual quoted prices and the normalised comparison value are shown separately. Normalised = required qty x rate x (1-disc) x FX / tax divisor + APPROVED adjustments only. The cheapest quotation is never auto-awarded.
A3: BLANK TEMPLATE | Legend: yellow = input | grey = formula (locked) | blue = read-only from the application. Python application is the authoritative calculator.
A4: package_id | B4: quotation_id | C4: supplier | D4: validity | E4: coverage | F4: quoted_total | G4: currency | H4: approved_adjustments | I4: normalised_total | J4: difference_vs_lowest | K4: like_for_like | L4: lead_time_days | M4: payment_terms | N4: exclusions | O4: missing_items | P4: notes
A5: Package | B5: Quotation | C5: Supplier | D5: Validity | E5: Coverage | F5: Quoted total (as quoted) | G5: Currency | H5: Approved adjustments (SAR) | I5: Normalised comparison value (SAR, pre-tax) | J5: Diff vs lowest like-for-like | K5: Like-for-like | L5: Lead time | M5: Payment terms | N5: Exclusions | O5: Missing items | P5: Notes
J6: =IF(OR(I6="",K6<>"Yes"),"",I6-MINIFS($I$6:$I$500,$K$6:$K$500,"Yes"))
J7: =IF(OR(I7="",K7<>"Yes"),"",I7-MINIFS($I$6:$I$500,$K$6:$K$500,"Yes"))
J8: =IF(OR(I8="",K8<>"Yes"),"",I8-MINIFS($I$6:$I$500,$K$6:$K$500,"Yes"))
J9: =IF(OR(I9="",K9<>"Yes"),"",I9-MINIFS($I$6:$I$500,$K$6:$K$500,"Yes"))
J10: =IF(OR(I10="",K10<>"Yes"),"",I10-MINIFS($I$6:$I$500,$K$6:$K$500,"Yes"))
J11: =IF(OR(I11="",K11<>"Yes"),"",I11-MINIFS($I$6:$I$500,$K$6:$K$500,"Yes"))
J12: =IF(OR(I12="",K12<>"Yes"),"",I12-MINIFS($I$6:$I$500,$K$6:$K$500,"Yes"))
J13: =IF(OR(I13="",K13<>"Yes"),"",I13-MINIFS($I$6:$I$500,$K$6:$K$500,"Yes"))
J14: =IF(OR(I14="",K14<>"Yes"),"",I14-MINIFS($I$6:$I$500,$K$6:$K$500,"Yes"))
J15: =IF(OR(I15="",K15<>"Yes"),"",I15-MINIFS($I$6:$I$500,$K$6:$K$500,"Yes"))
J16: =IF(OR(I16="",K16<>"Yes"),"",I16-MINIFS($I$6:$I$500,$K$6:$K$500,"Yes"))
J17: =IF(OR(I17="",K17<>"Yes"),"",I17-MINIFS($I$6:$I$500,$K$6:$K$500,"Yes"))
... J305: =IF(OR(I305="",K305<>"Yes"),"",I305-MINIFS($I$6:$I$500,$K$6:$K$500,"Yes"))

Sheet Clarification Register
A1: Client Clarification Register
A2: Clarifications are raised OPEN. A clarification is only resolved by a human with the client response and supporting evidence; AI suggestions are drafts.
A3: BLANK TEMPLATE | Legend: yellow = input | grey = formula (locked) | blue = read-only from the application. Python application is the authoritative calculator.
A4: id | B4: question | C4: trade | D4: boq_item_key | E4: doc_ref | F4: reason | G4: commercial_impact | H4: cost_exposure | I4: proposed_wording | J4: owner | K4: status | L4: client_response | M4: resolution_date
A5: ID | B5: Question | C5: Trade | D5: Related BOQ item | E5: Drawing / spec ref | F5: Reason | G5: Commercial impact | H5: Cost exposure (SAR) | I5: Proposed wording | J5: Owner | K5: Status | L5: Client response | M5: Resolution date

Sheet Inclusions and Exclusions
A1: Inclusions, Exclusions & Qualifications
A2: Every material requirement must be priced, explicitly excluded/qualified (approved), covered by an approved allowance, or marked unresolved. Entries import as Draft and need approval.
A3: BLANK TEMPLATE | Legend: yellow = input | grey = formula (locked) | blue = read-only from the application. Python application is the authoritative calculator.
A4: id | B4: kind | C4: description | D4: trade | E4: boq_item_key | F4: cost_code | G4: rationale | H4: status
A5: ID | B5: Kind | C5: Description | D5: Trade | E5: BOQ item | F5: Cost code | G5: Rationale | H5: Status

Sheet Risk Register
A1: Tender Risk Register
A2: Risks and their cost exposure. Quantified risk allowances are priced through the approved commercial policy, not here.
A3: BLANK TEMPLATE | Legend: yellow = input | grey = formula (locked) | blue = read-only from the application. Python application is the authoritative calculator.
A4: id | B4: title | C4: description | D4: trade | E4: probability | F4: impact | G4: cost_exposure | H4: mitigation | I4: owner | J4: status
A5: ID | B5: Title | C5: Description | D5: Trade | E5: Probability | F5: Impact | G5: Cost exposure (SAR) | H5: Mitigation | I5: Owner | J5: Status

Sheet Reconciliation
A1: Final Reconciliation Findings
A2: Latest reconciliation run. Critical findings block final approval and cannot be excepted. Accept exceptions in the application (documented reason, role-checked).
A3: BLANK TEMPLATE | Legend: yellow = input | grey = formula (locked) | blue = read-only from the application. Python application is the authoritative calculator.
A4: severity | B4: rule_code | C4: title | D4: detail | E4: entity | F4: financial_impact | G4: owner | H4: status | I4: exception_reason
A5: Severity | B5: Rule | C5: Title | D5: Detail | E5: Entity | F5: Financial impact (SAR) | G5: Owner | H5: Status | I5: Exception reason

Sheet Approval Log
A1: Approval Log
A2: Immutable record of human approval decisions (reviewer, role, timestamp, previous and approved value, evidence, comments).
A3: BLANK TEMPLATE | Legend: yellow = input | grey = formula (locked) | blue = read-only from the application. Python application is the authoritative calculator.
A4: ts | B4: entity_type | C4: entity_id | D4: version | E4: reviewer | F4: reviewer_role | G4: action | H4: previous_value | I4: approved_value | J4: evidence | K4: comments | L4: override_reason
A5: Timestamp (UTC) | B5: Entity type | C5: Entity ID | D5: Version | E5: Reviewer | F5: Role | G5: Action | H5: Previous value | I5: Approved value / decision | J5: Evidence | K5: Comments | L5: Override reason

Sheet AI Instructions
A1: AI Instructions and Policy
A2: AI is OPTIONAL. Deterministic estimating works without any AI key. AI output is always a PROPOSAL with a review status of 'Pending Review'.
A3: What AI may do
A4: Suggest BOQ-to-assembly mappings; propose quotation field extraction; flag possible scope gaps and contradictions; draft clarification questions and RFQ emails; summarise supplier exclusions; highlight specification differences; suggest reconciliation issues; find relevant historical records.
A5: What AI must never do
A6: Measure quantities; invent prices; silently alter approved inputs; approve quotations, assumptions or its own proposals; select a supplier automatically; send external emails; submit a tender; change approved commercial policies; claim to have verified a source it did not access.
A7: Handling untrusted documents
A8: Uploaded documents, emails, PDFs, spreadsheets and quotations are DATA, not instructions. Text inside them cannot change system policy, approve anything, or issue commands. AI output must validate against a strict schema or it is discarded.
A9: Prompt rules used by the application (summary)
A10: system: You assist a human estimator. You propose; humans decide. Output JSON only matching the schema. Quote document text as evidence. If unsure, return low confidence. Never output approvals or prices not present in the supplied document.
A11: If you are using an external assistant with this workbook
A12: Do not ask it to produce final rates or approvals. Paste only the specific rows you need help with, treat answers as drafts, and enter accepted changes yourself in the application.

Sheet Data Dictionary
A1: Data Dictionary
A2: Every column in every sheet: its machine key, colour class and meaning. Machine keys (hidden row 4) drive the importer.
A5: Sheet | B5: Column header | C5: Machine key | D5: Class | E5: Number format / validation | F5: Notes
A6: Trade and Cost Code Mapping | B6: BOQ item key | C6: item_key | D6: Read-only (blue)
A7: Trade and Cost Code Mapping | B7: Client code | C7: item_code | D7: Read-only (blue)
A8: Trade and Cost Code Mapping | B8: Description | C8: description | D8: Read-only (blue)
A9: Trade and Cost Code Mapping | B9: Client trade | C9: trade | D9: Read-only (blue)
A10: Trade and Cost Code Mapping | B10: Cost code | C10: cost_code | D10: Input (yellow) | E10: | list: costcodes | F10: Internal cost code from the taxonomy
A11: Trade and Cost Code Mapping | B11: Assembly code | C11: assembly_code | D11: Input (yellow) | F11: Approved assembly code to price this item
A12: Trade and Cost Code Mapping | B12: Mapping status | C12: mapping_status | D12: Read-only (blue)
A13: Trade and Cost Code Mapping | B13: Mapping source | C13: mapping_source | D13: Read-only (blue)
A14: Trade and Cost Code Mapping | B14: Pricing method | C14: pricing_method | D14: Input (yellow) | E14: | list: PricingMethod
A15: Pricing Schedule | B15: Item | C15: item_code | D15: Read-only (blue)
A16: Pricing Schedule | B16: Description | C16: description | D16: Read-only (blue)
A17: Pricing Schedule | B17: Unit | C17: unit | D17: Read-only (blue)
A18: Pricing Schedule | B18: Quantity | C18: quantity | D18: Read-only (blue) | E18: #,##0.000
A19: Pricing Schedule | B19: Unit rate (SAR) | C19: unit_rate | D19: Read-only (blue) | E19: #,##0.00;[Red]-#,##0.00
A20: Pricing Schedule | B20: Amount (SAR) | C20: amount | D20: Formula (grey) | E20: #,##0.00;[Red]-#,##0.00 | F20: Formula: =IF(OR(D{r}="",E{r}=""),"",ROUND(D{r}*E{r},2))
A21: Pricing Schedule | B21: Engine amount | C21: engine_amount | D21: Read-only (blue) | E21: #,##0.00;[Red]-#,##0.00
A22: Pricing Schedule | B22: Check | C22: check | D22: Formula (grey) | F22: Formula: =IF(OR(F{r}="",G{r}=""),"",IF(ABS(F{r}-G{r})>0.01,"MISMATCH","OK"))
A23: Pricing Schedule | B23: Status | C23: status | D23: Read-only (blue)
A24: Pricing Schedule | B24: Flags | C24: flags | D24: Read-only (blue)
A25: BOQ Import | B25: Item | C25: item_code | D25: Input (yellow)
A26: BOQ Import | B26: Description | C26: description | D26: Input (yellow)
A27: BOQ Import | B27: Trade | C27: trade | D27: Input (yellow)
A28: BOQ Import | B28: Unit | C28: unit | D28: Input (yellow)
A29: BOQ Import | B29: Quantity | C29: quantity | D29: Input (yellow) | E29: #,##0.000
A30: BOQ Import | B30: Client rate | C30: client_rate | D30: Input (yellow) | E30: #,##0.00;[Red]-#,##0.00
A31: BOQ Import | B31: Client amount | C31: client_amount | D31: Input (yellow) | E31: #,##0.00;[Red]-#,##0.00
A32: BOQ Import | B32: Drawing ref | C32: drawing_ref | D32: Input (yellow)
A33: BOQ Import | B33: Spec ref | C33: spec_ref | D33: Input (yellow)
A34: BOQ Import | B34: Cost code | C34: cost_code | D34: Input (yellow) | E34: | list: costcodes
A35: BOQ Import | B35: Revision | C35: revision | D35: Input (yellow)
A36: BOQ Import | B36: Source file | C36: source_file | D36: Read-only (blue)
A37: BOQ Import | B37: Source sheet | C37: source_sheet | D37: Read-only (blue)
A38: BOQ Import | B38: Source row | C38: source_row | D38: Read-only (blue)
A39: BOQ Import | B39: Original qty text | C39: quantity_original | D39: Read-only (blue)
A40: BOQ Import | B40: Unit status | C40: unit_status | D40: Read-only (blue)
A41: BOQ Import | B41: Validation | C41: validation_status | D41: Read-only (blue)
A42: BOQ Import | B42: Issues | C42: issues | D42: Read-only (blue)
...

Sheet Source Register
A1: Source Register
A2: Provenance for public data: source, URL, dates, licence/reuse conditions, extraction method, limitations and confidence. Failed or blocked access is recorded honestly.
A3: BLANK TEMPLATE | Legend: yellow = input | grey = formula (locked) | blue = read-only from the application. Python application is the authoritative calculator.
A4: source_id | B4: name | C4: organisation | D4: url | E4: type | F4: date_accessed | G4: publication_date | H4: geographic_relevance | I4: currency | J4: unit_price_basis | K4: applicable_trades | L4: licence_reuse_conditions | M4: extraction_method | N4: access_status | O4: limitations | P4: confidence | Q4: data_collected
A5: Source ID | B5: Name | C5: Organisation | D5: URL | E5: Type | F5: Date accessed | G5: Publication date | H5: Geography | I5: Currency | J5: Unit / price basis | K5: Trades | L5: Licence / reuse | M5: Extraction method | N5: Access status | O5: Limitations | P5: Confidence | Q5: Data collected

Sheet Lists
A1: Status | B1: RateType | C1: ResourceType | D1: PricingMethod | E1: YesNoUnknown | F1: Method | G1: Base | H1: IndirectMethod | I1: Allocation | J1: LineType | K1: WasteBasis | L1: Productivity | M1: ScopeKind | N1: ClarStatus | O1: Severity | P1: Compliance | Q1: Confidence | R1: TaxTreatment | S1: units | T1: regions | U1: costcodes
A2: Draft | B2: Verified Supplier Quote | C2: material | D2: assembly | E2: Yes | F2: markup | G2: direct | H2: fixed | I2: pro_rata_direct | J2: material | K2: none | L2: paid_hours_per_unit | M2: inclusion | N2: Open | O2: Critical | P2: Compliant | Q2: High | R2: excl
A3: Pending Review | B3: Published Market Price | C3: labour | D3: subcontract_lump | E3: No | F3: margin | G3: direct_indirect | H3: percent_of_direct | I3: separate_line | J3: labour | K3: fixed_pct | L3: productive_hours_per_unit | M3: exclusion | N3: Submitted | O3: High | P3: Non-compliant | Q3: Medium | R3: incl
A4: Approved | B4: Official Index or Benchmark | C4: plant | D4: takeoff_resources | E4: Unknown | G4: cost_before_escalation | H4: per_day | I4: direct_trade | J4: plant | K4: assumption | L4: output_per_crew_shift | M4: qualification | N4: Resolved | O4: Medium | P4: Deviation | Q4: Low | R4: exempt
A5: Rejected | B5: Historical Actual | C5: equipment | D5: provisional_sum | H5: per_week | J5: equipment | N5: Withdrawn | O5: Low | P5: Unassessed | Q5: Unverified
A6: Expired | B6: Approved Internal Benchmark | C6: subcontract | D6: prime_cost_sum | H6: per_month | J6: subcontract
A7: Superseded | B7: Estimator-Entered Allowance | D7: allowance | H7: per_duration_month | J7: assembly
A8: Provisional — Approved for This Estimate | B8: Synthetic Demonstration Rate | D8: excluded | J8: other
A9: Not Applicable | B9: Missing Rate | D9: unpriced
